Workbook

Sheet 1_Daily_Social_Matrix
A1: Date | C1: 18 October 2026
A2: Dimensions | C2: posts | E2: followers | G2: following | I2: comments | K2: dms
A3: Method | Profile | B3: Platform | C3: simali | D3: tafa | E3: simali | F3: tafa | G3: simali | H3: tafa | I3: simali | J3: tafa | K3: simali | L3: tafa
A4: Buffer_A | B4: x | C4: 0 | D4: 0 | I4: 0 | J4: 0 | K4: 0 | L4: 0
B5: linkedin | C5: 0 | D5: 0 | I5: 0 | J5: 0 | K5: 0 | L5: 0
B6: pinterest | C6: 0 | D6: 0 | I6: 0 | J6: 0 | K6: 0 | L6: 0
A7: Buffer_B | B7: facebook | C7: 0 | D7: 0 | I7: 0 | J7: 0 | K7: 0 | L7: 0
B8: instagram | C8: 0 | D8: 0 | I8: 0 | J8: 0 | K8: 0 | L8: 0
B9: threads | C9: 0 | D9: 0 | I9: 0 | J9: 0 | K9: 0 | L9: 0
A10: Buffer_C | B10: youtube | C10: 0 | D10: 0 | I10: 0 | J10: 0 | K10: 0 | L10: 0
B11: tiktok | C11: 0 | D11: 0 | I11: 0 | J11: 0 | K11: 0 | L11: 0
B12: gbp | C12: 0 | D12: 0 | I12: 0 | J12: 0 | K12: 0 | L12: 0
A13: Native | B13: bluesky | C13: 0 | D13: 0 | I13: 0 | J13: 0 | K13: 0 | L13: 0
B14: dev.to | C14: 0 | D14: 0 | I14: 0 | J14: 0 | K14: 0 | L14: 0
B15: hashnode | C15: 0 | D15: 0 | I15: 0 | J15: 0 | K15: 0 | L15: 0
B16: mastodon | C16: 0 | D16: 0 | I16: 0 | J16: 0 | K16: 0 | L16: 0
B17: whop | C17: 0 | D17: 0 | I17: 0 | J17: 0 | K17: 0 | L17: 0
B18: github | C18: 0 | D18: 0 | I18: 0 | J18: 0 | K18: 0 | L18: 0
B19: tumblr | C19: 0 | D19: 0 | I19: 0 | J19: 0 | K19: 0 | L19: 0
B20: discord | C20: 0 | D20: 0 | I20: 0 | J20: 0 | K20: 0 | L20: 0
B21: telegram | C21: 0 | D21: 0 | I21: 0 | J21: 0 | K21: 0 | L21: 0
B22: nostr | C22: 0 | D22: 0 | I22: 0 | J22: 0 | K22: 0 | L22: 0
B23: blogspot | C23: 0 | D23: 0 | I23: 0 | J23: 0 | K23: 0 | L23: 0
A24: Manual | B24: reddit | C24: 0 | D24: 0 | I24: 0 | J24: 0 | K24: 0 | L24: 0
B25: medium | C25: 0 | D25: 0 | I25: 0 | J25: 0 | K25: 0 | L25: 0
B26: quora | C26: 0 | D26: 0 | I26: 0 | J26: 0 | K26: 0 | L26: 0
B27: g. sites | C27: 0 | D27: 0 | I27: 0 | J27: 0 | K27: 0 | L27: 0
B28: whatsapp_status | C28: 0 | D28: 0 | I28: 0 | J28: 0 | K28: 0 | L28: 0
A29: DAILY TOTAL | B29: All 25 Channels | C29: =SUM(C4:C28) | D29: =SUM(D4:D28) | I29: =SUM(I4:I28) | J29: =SUM(J4:J28) | K29: =SUM(K4:K28) | L29: =SUM(L4:L28)
A31: Date | C31: 19 October 2026
A32: Dimensions | C32: posts | E32: followers | G32: following | I32: comments | K32: dms
A33: Method | Profile | B33: Platform | C33: simali | D33: tafa | E33: simali | F33: tafa | G33: simali | H33: tafa | I33: simali | J33: tafa | K33: simali | L33: tafa
A34: Buffer_A | B34: x | C34: 0 | D34: 0 | I34: 0 | J34: 0 | K34: 0 | L34: 0
B35: linkedin | C35: 0 | D35: 0 | I35: 0 | J35: 0 | K35: 0 | L35: 0
B36: pinterest | C36: 0 | D36: 0 | I36: 0 | J36: 0 | K36: 0 | L36: 0
A37: Buffer_B | B37: facebook | C37: 0 | D37: 0 | I37: 0 | J37: 0 | K37: 0 | L37: 0
B38: instagram | C38: 0 | D38: 0 | I38: 0 | J38: 0 | K38: 0 | L38: 0
B39: threads | C39: 0 | D39: 0 | I39: 0 | J39: 0 | K39: 0 | L39: 0
A40: Buffer_C | B40: youtube | C40: 0 | D40: 0 | I40: 0 | J40: 0 | K40: 0 | L40: 0
B41: tiktok | C41: 0 | D41: 0 | I41: 0 | J41: 0 | K41: 0 | L41: 0
...

Sheet 2_Daily_Checklist
A1: Date | B1: Operator | C1: Morning Rounds Approved? | D1: Social/Lead Replies Sent (Target: 30) | E1: Agency Follow-Ups Sent (Target: 15) | F1: Affiliates Contacted (Target: 3) | G1: Trials Started Today (Target: 2) | H1: $19 Setup Packs Sold | I1: $49/mo DFY Sold | J1: $306/mo Solo Sold | K1: $613/mo Studio Sold | L1: $920/mo Sovereign Sold | M1: Cash Collected Today ($) | N1: New MRR Added Today ($/mo) | O1: Key Wins / Blockers / Notes
A2: 2026-10-18 | B2: simali | C2: YES | D2: 30 | E2: 15 | F2: 3 | G2: 2 | H2: 0 | I2: 0 | J2: 0 | K2: 0 | L2: 0 | M2: =H2*19+I2*49+J2*306+K2*613+L2*920 | N2: =I2*49+J2*306+K2*613+L2*920 | O2: Approved morning rounds across 16 countries; launched 30-video rotation
A3: 2026-10-18 | B3: tafa | C3: YES | D3: 30 | E3: 15 | F3: 3 | G3: 2 | H3: 0 | I3: 0 | J3: 0 | K3: 0 | L3: 0 | M3: =H3*19+I3*49+J3*306+K3*613+L3*920 | N3: =I3*49+J3*306+K3*613+L3*920 | O3: Followed up with warm recruitment leads & sent $19 Setup / $49 DFY links
A4: 2026-10-19 | B4: simali | C4: YES | D4: 0 | E4: 0 | F4: 0 | G4: 0 | H4: 0 | I4: 0 | J4: 0 | K4: 0 | L4: 0 | M4: =H4*19+I4*49+J4*306+K4*613+L4*920 | N4: =I4*49+J4*306+K4*613+L4*920
A5: 2026-10-19 | B5: tafa | C5: YES | D5: 0 | E5: 0 | F5: 0 | G5: 0 | H5: 0 | I5: 0 | J5: 0 | K5: 0 | L5: 0 | M5: =H5*19+I5*49+J5*306+K5*613+L5*920 | N5: =I5*49+J5*306+K5*613+L5*920

Sheet 3_CRM_Who_We_Talked_To
A1: Lead ID | B1: Contact / Company Name | C1: Country | D1: Segment | E1: Channel | F1: Owner (simali/tafa) | G1: Last Talked Date | H1: What We Discussed / Did Today | I1: Stage | J1: Next Follow-Up Date (Talk To Tomorrow) | K1: Next Action Required | L1: Phone / WhatsApp | M1: Email / Handle | N1: Website / Link | O1: Deal Value ($) | P1: MRR Value ($/mo) | Q1: Source
A2: LEAD-001 | B2: Harare Executive Search Desk | C2: ZW | D2: Agency | E2: WhatsApp | F2: simali | G2: 2026-10-18 | H2: Sent Studio promo video + 7-day /trial link; wants 15-candidate seat demo | I2: Trial Sent | J2: 2026-10-19 | K2: Walk through /intake link & close $613/mo Studio plan | L2: +263 78 460 0904 | M2: simalidudu@gmail.com | N2: https://getstpi.pages.dev | O2: 613 | P2: 613 | Q2: stpi-leads
A3: LEAD-002 | B3: Sandton Finance Candidate | C3: ZA | D3: Job Seeker | E3: LinkedIn | F3: tafa | G3: 2026-10-18 | H3: Audited CV; pitched $19 Setup Pack + $49/mo DFY Placement across ZA & BW | I3: $49 DFY Pitch | J3: 2026-10-19 | K3: Send Whop $49/mo DFY checkout link (ch_Si8xefqAIZZzm3R) | L3: +27 82 000 0000 | M3: tafadzwamchikanya@gmail.com | N3: https://whop.com/stpi | O3: 49 | P3: 49 | Q3: social_watch
A4: LEAD-003 | B4: Nairobi Career Coach Partner | C4: KE | D4: Affiliate | E4: X / DM | F4: simali | G4: 2026-10-18 | H4: Shared 30% Whop affiliate program + 30 promo videos repo | I4: Affiliate Onboarding | J4: 2026-10-19 | K4: Confirm ?a= handle is live and schedule first TikTok/LinkedIn post | L4: +254 700 000 000 | M4: @stpi_partner | N4: https://whop.com/stpi | O4: 306 | P4: 306 | Q4: manual

Sheet 4_Tomorrow_Queue
A1: Owner (simali/tafa) | B1: Next Follow-Up Date | C1: Contact / Company Name | D1: Country | E1: Segment | F1: Channel | G1: Current Stage | H1: What We Discussed Last | I1: Next Action To Take Today | J1: Phone / WhatsApp | K1: Email / Handle | L1: Deal Value ($)
A2: simali | B2: 2026-10-19 | C2: Harare Executive Search Desk | D2: ZW | E2: Agency | F2: WhatsApp | G2: Trial Sent | H2: Sent Studio promo video + 7-day /trial link; wants 15-candidate seat demo | I2: Walk through /intake link & close $613/mo Studio plan | J2: +263 78 460 0904 | K2: simalidudu@gmail.com | L2: 613
A3: tafa | B3: 2026-10-19 | C3: Sandton Finance Candidate | D3: ZA | E3: Job Seeker | F3: LinkedIn | G3: $49 DFY Pitch | H3: Audited CV; pitched $19 Setup Pack + $49/mo DFY Placement across ZA & BW | I3: Send Whop $49/mo DFY checkout link (ch_Si8xefqAIZZzm3R) | J3: +27 82 000 0000 | K3: tafadzwamchikanya@gmail.com | L3: 49
A4: simali | B4: 2026-10-19 | C4: Nairobi Career Coach Partner | D4: KE | E4: Affiliate | F4: X / DM | G4: Affiliate Onboarding | H4: Shared 30% Whop affiliate program + 30 promo videos repo | I4: Confirm ?a= handle is live and schedule first TikTok/LinkedIn post | J4: +254 700 000 000 | K4: @stpi_partner | L4: 306

Sheet 5_Seller_Scoreboard
A1: Operator / Seller | B1: Role | C1: CRM Contacts Logged | D1: Social/Lead Replies Sent | E1: Agency Follow-Ups Sent | F1: Trials Started | G1: $19 Setup Packs Sold | H1: $49/mo DFY Clients Sold | I1: Total Cash Generated ($) | J1: Total MRR Generated ($/mo) | K1: 30% Seller Commission ($)
A2: simali | B2: Founder / Company | C2: =COUNTIF('3_CRM_Who_We_Talked_To'!F2:F1000,"simali") | D2: =SUMIF('2_Daily_Checklist'!B2:B1000,"simali",'2_Daily_Checklist'!D2:D1000) | E2: =SUMIF('2_Daily_Checklist'!B2:B1000,"simali",'2_Daily_Checklist'!E2:E1000) | F2: =SUMIF('2_Daily_Checklist'!B2:B1000,"simali",'2_Daily_Checklist'!G2:G1000) | G2: =SUMIF('2_Daily_Checklist'!B2:B1000,"simali",'2_Daily_Checklist'!H2:H1000) | H2: =SUMIF('2_Daily_Checklist'!B2:B1000,"simali",'2_Daily_Checklist'!I2:I1000) | I2: =SUMIF('2_Daily_Checklist'!B2:B1000,"simali",'2_Daily_Checklist'!M2:M1000) | J2: =SUMIF('2_Daily_Checklist'!B2:B1000,"simali",'2_Daily_Checklist'!N2:N1000) | K2: 0
A3: tafa | B3: Partner / Seller A | C3: =COUNTIF('3_CRM_Who_We_Talked_To'!F2:F1000,"tafa") | D3: =SUMIF('2_Daily_Checklist'!B2:B1000,"tafa",'2_Daily_Checklist'!D2:D1000) | E3: =SUMIF('2_Daily_Checklist'!B2:B1000,"tafa",'2_Daily_Checklist'!E2:E1000) | F3: =SUMIF('2_Daily_Checklist'!B2:B1000,"tafa",'2_Daily_Checklist'!G2:G1000) | G3: =SUMIF('2_Daily_Checklist'!B2:B1000,"tafa",'2_Daily_Checklist'!H2:H1000) | H3: =SUMIF('2_Daily_Checklist'!B2:B1000,"tafa",'2_Daily_Checklist'!I2:I1000) | I3: =SUMIF('2_Daily_Checklist'!B2:B1000,"tafa",'2_Daily_Checklist'!M2:M1000) | J3: =SUMIF('2_Daily_Checklist'!B2:B1000,"tafa",'2_Daily_Checklist'!N2:N1000) | K3: =I3*0.30

Sheet 6_Dec16_10K_8K_Tracker
A1: Metric | B1: Goal by Dec 16, 2026 | C1: Live Actual | D1: Remaining Gap | E1: % Complete | F1: Target Mix / Notes
A2: Active MRR ($/mo) | B2: 8000 | C2: =SUM('2_Daily_Checklist'!N2:N1000) | D2: =MAX(0,B2-C2) | E2: =C2/B2 | F2: 50 DFY ($49) + 8 Solo ($306) + 4 Studio ($613) + 1 Sovereign ($920) = $8,270/mo
A3: Cash In-Hand ($) | B3: 10000 | C3: =SUM('2_Daily_Checklist'!M2:M1000) | D3: =MAX(0,B3-C3) | E3: =C3/B3 | F3: 100 Setup ($19) + Monthly Plans + W1-W4 Renewals = $12,450 Gross / >$10,500 Net
A5: Week | B5: Dates (2026) | C5: Weekly Sales Target | D5: Target Cumulative MRR ($/mo) | E5: Target Cumulative Cash ($) | F5: Completed?
A6: Week 1 | B6: Oct 19 - Oct 25 | C6: 10 Setup ($19) · 5 DFY ($49) · 1 Solo ($306) | D6: 551 | E6: 680 | F6: PENDING
A7: Week 2 | B7: Oct 26 - Nov 01 | C7: 12 Setup ($19) · 6 DFY ($49) · 1 Solo ($306) | D7: 1151 | E7: 1430 | F7: PENDING
A8: Week 3 | B8: Nov 02 - Nov 08 | C8: 12 Setup ($19) · 6 DFY ($49) · 1 Solo ($306) · 1 Studio ($613) | D8: 2364 | E8: 2760 | F8: PENDING
A9: Week 4 | B9: Nov 09 - Nov 15 | C9: 14 Setup ($19) · 7 DFY ($49) · 1 Solo ($306) · 1 Studio ($613) | D9: 3626 | E9: 4180 | F9: PENDING
A10: Week 5 | B10: Nov 16 - Nov 22 | C10: 14 Setup ($19) · 7 DFY ($49) · 1 Solo ($306) + W1 Renewals | D10: 4275 | E10: 5530 | F10: PENDING
A11: Week 6 | B11: Nov 23 - Nov 29 | C11: 14 Setup ($19) · 7 DFY ($49) · 1 Solo ($306) · 1 Studio ($613) + W2 Renewals | D11: 5537 | E11: 7460 | F11: PENDING
A12: Week 7 | B12: Nov 30 - Dec 06 | C12: 12 Setup ($19) · 6 DFY ($49) · 1 Solo ($306) · 1 Studio ($613) + W3 Renewals | D12: 6750 | E12: 9820 | F12: PENDING
A13: Week 8 | B13: Dec 07 - Dec 16 | C13: 12 Setup ($19) · 6 DFY ($49) · 1 Solo ($306) · 1 Sovereign ($920) + W4 Renewals | D13: 8270 | E13: 12450 | F13: PENDING
